Workbook

Sheet sales_pipeline
A1: opportunity_id | B1: Opportunity Type | C1: sales_agent | D1: sales_agent_id | E1: manager | F1: regional_office | G1: product | H1: series | I1: account | J1: sector | K1: account_tier | L1: deal_stage | M1: Win/Loss Reason | N1: Competitor | O1: engage_date | P1: close_date | Q1: price_per_unit | R1: Units Sold | S1: closing_price
A2: 1C1I7A6R | B2: Expansion | C2: Moses Frase | D2: =_xlfn.XLOOKUP(C2,sales_teams!A:A,sales_teams!B:B,"") -> C62195 | E2: =_xlfn.XLOOKUP(C2,sales_teams!A:A,sales_teams!C:C,"") -> Dustin Brinkmann | F2: =_xlfn.XLOOKUP(C2,sales_teams!A:A,sales_teams!D:D,"") -> Central | G2: GTX Plus Basic | H2: =_xlfn.XLOOKUP(G2,products!A:A,products!B:B,"") -> GTX | I2: Cancity | J2: =_xlfn.XLOOKUP(I2,accounts!A:A,accounts!B:B,"") -> retail | K2: =_xlfn.XLOOKUP(I2,accounts!A:A,accounts!F:F,"") -> Mid-Market | L2: Won | M2: Executive Relationship | N2: Ivy Green-Tech | O2: 42663 | P2: 42795 | Q2: =_xlfn.XLOOKUP(G2,products!A:A,products!C:C,"") -> 1096 | R2: 50 | S2: =Q2*R2 -> 54800
A3: Z063OYW0 | B3: Acquisition | C3: Darcel Schlecht | D3: =_xlfn.XLOOKUP(C3,sales_teams!A:A,sales_teams!B:B,"") -> C486814 | E3: =_xlfn.XLOOKUP(C3,sales_teams!A:A,sales_teams!C:C,"") -> Melvin Marxen | F3: =_xlfn.XLOOKUP(C3,sales_teams!A:A,sales_teams!D:D,"") -> Central | G3: GTX Pro | H3: =_xlfn.XLOOKUP(G3,products!A:A,products!B:B,"") -> GTX | I3: Isdom | J3: =_xlfn.XLOOKUP(I3,accounts!A:A,accounts!B:B,"") -> medical | K3: =_xlfn.XLOOKUP(I3,accounts!A:A,accounts!F:F,"") -> Mid-Market | L3: Won | M3: Advanced Technology | N3: Ivy Green-Tech | O3: 42668 | P3: 42805 | Q3: =_xlfn.XLOOKUP(G3,products!A:A,products!C:C,"") -> 4821 | R3: 37 | S3: =Q3*R3 -> 178377
A4: EC4QE1BX | B4: Expansion | C4: Darcel Schlecht | D4: =_xlfn.XLOOKUP(C4,sales_teams!A:A,sales_teams!B:B,"") -> C486814 | E4: =_xlfn.XLOOKUP(C4,sales_teams!A:A,sales_teams!C:C,"") -> Melvin Marxen | F4: =_xlfn.XLOOKUP(C4,sales_teams!A:A,sales_teams!D:D,"") -> Central | G4: MG Special | H4: =_xlfn.XLOOKUP(G4,products!A:A,products!B:B,"") -> MG | I4: Cancity | J4: =_xlfn.XLOOKUP(I4,accounts!A:A,accounts!B:B,"") -> retail | K4: =_xlfn.XLOOKUP(I4,accounts!A:A,accounts!F:F,"") -> Mid-Market | L4: Won | M4: Brand Uniqueness | N4: Falconia Enterprises | O4: 42668 | P4: 42801 | Q4: =_xlfn.XLOOKUP(G4,products!A:A,products!C:C,"") -> 55 | R4: 8 | S4: =Q4*R4 -> 440
A5: MV1LWRNH | B5: Expansion | C5: Moses Frase | D5: =_xlfn.XLOOKUP(C5,sales_teams!A:A,sales_teams!B:B,"") -> C62195 | E5: =_xlfn.XLOOKUP(C5,sales_teams!A:A,sales_teams!C:C,"") -> Dustin Brinkmann | F5: =_xlfn.XLOOKUP(C5,sales_teams!A:A,sales_teams!D:D,"") -> Central | G5: GTX Basic | H5: =_xlfn.XLOOKUP(G5,products!A:A,products!B:B,"") -> GTX | I5: Codehow | J5: =_xlfn.XLOOKUP(I5,accounts!A:A,accounts!B:B,"") -> software | K5: =_xlfn.XLOOKUP(I5,accounts!A:A,accounts!F:F,"") -> Mid-Market | L5: Won | M5: Advanced Technology | N5: Ivy Green-Tech | O5: 42668 | P5: 42803 | Q5: =_xlfn.XLOOKUP(G5,products!A:A,products!C:C,"") -> 550 | R5: 32 | S5: =Q5*R5 -> 17600
A6: PE84CX4O | B6: Retention | C6: Zane Levy | D6: =_xlfn.XLOOKUP(C6,sales_teams!A:A,sales_teams!B:B,"") -> W202814 | E6: =_xlfn.XLOOKUP(C6,sales_teams!A:A,sales_teams!C:C,"") -> Summer Sewald | F6: =_xlfn.XLOOKUP(C6,sales_teams!A:A,sales_teams!D:D,"") -> West | G6: GTX Basic | H6: =_xlfn.XLOOKUP(G6,products!A:A,products!B:B,"") -> GTX | I6: Hatfan | J6: =_xlfn.XLOOKUP(I6,accounts!A:A,accounts!B:B,"") -> services | K6: =_xlfn.XLOOKUP(I6,accounts!A:A,accounts!F:F,"") -> Mid-Market | L6: Won | M6: Product Superiority | N6: Cobblepot Exports | O6: 42668 | P6: 42796 | Q6: =_xlfn.XLOOKUP(G6,products!A:A,products!C:C,"") -> 550 | R6: 5 | S6: =Q6*R6 -> 2750
A7: ZNBS69V1 | B7: Expansion | C7: Anna Snelling | D7: =_xlfn.XLOOKUP(C7,sales_teams!A:A,sales_teams!B:B,"") -> C265891 | E7: =_xlfn.XLOOKUP(C7,sales_teams!A:A,sales_teams!C:C,"") -> Dustin Brinkmann | F7: =_xlfn.XLOOKUP(C7,sales_teams!A:A,sales_teams!D:D,"") -> Central | G7: MG Special | H7: =_xlfn.XLOOKUP(G7,products!A:A,products!B:B,"") -> MG | I7: Ron-tech | J7: =_xlfn.XLOOKUP(I7,accounts!A:A,accounts!B:B,"") -> medical | K7: =_xlfn.XLOOKUP(I7,accounts!A:A,accounts!F:F,"") -> Enterprise | L7: Won | M7: Strategic Timing | N7: Cobblepot Exports | O7: 42672 | P7: 42795 | Q7: =_xlfn.XLOOKUP(G7,products!A:A,products!C:C,"") -> 55 | R7: 36 | S7: =Q7*R7 -> 1980
A8: 9ME3374G | B8: Retention | C8: Vicki Laflamme | D8: =_xlfn.XLOOKUP(C8,sales_teams!A:A,sales_teams!B:B,"") -> W975078 | E8: =_xlfn.XLOOKUP(C8,sales_teams!A:A,sales_teams!C:C,"") -> Celia Rouche | F8: =_xlfn.XLOOKUP(C8,sales_teams!A:A,sales_teams!D:D,"") -> West | G8: MG Special | H8: =_xlfn.XLOOKUP(G8,products!A:A,products!B:B,"") -> MG | I8: J-Texon | J8: =_xlfn.XLOOKUP(I8,accounts!A:A,accounts!B:B,"") -> retail | K8: =_xlfn.XLOOKUP(I8,accounts!A:A,accounts!F:F,"") -> Mid-Market | L8: Won | M8: Brand Uniqueness | N8: Enigma Analytics | O8: 42673 | P8: 42796 | Q8: =_xlfn.XLOOKUP(G8,products!A:A,products!C:C,"") -> 55 | R8: 27 | S8: =Q8*R8 -> 1485
A9: 7GN8Q4LL | B9: Diversification | C9: Markita Hansen | D9: =_xlfn.XLOOKUP(C9,sales_teams!A:A,sales_teams!B:B,"") -> W337844 | E9: =_xlfn.XLOOKUP(C9,sales_teams!A:A,sales_teams!C:C,"") -> Celia Rouche | F9: =_xlfn.XLOOKUP(C9,sales_teams!A:A,sales_teams!D:D,"") -> West | G9: GTX Basic | H9: =_xlfn.XLOOKUP(G9,products!A:A,products!B:B,"") -> GTX | I9: Cheers | J9: =_xlfn.XLOOKUP(I9,accounts!A:A,accounts!B:B,"") -> entertainment | K9: =_xlfn.XLOOKUP(I9,accounts!A:A,accounts!F:F,"") -> Enterprise | L9: Won | M9: Executive Relationship | N9: Falconia Enterprises | O9: 42675 | P9: 42801 | Q9: =_xlfn.XLOOKUP(G9,products!A:A,products!C:C,"") -> 550 | R9: 2 | S9: =Q9*R9 -> 1100
A10: OLK9LKZB | B10: Acquisition | C10: Niesha Huffines | D10: =_xlfn.XLOOKUP(C10,sales_teams!A:A,sales_teams!B:B,"") -> C961860 | E10: =_xlfn.XLOOKUP(C10,sales_teams!A:A,sales_teams!C:C,"") -> Melvin Marxen | F10: =_xlfn.XLOOKUP(C10,sales_teams!A:A,sales_teams!D:D,"") -> Central | G10: GTX Plus Basic | H10: =_xlfn.XLOOKUP(G10,products!A:A,products!B:B,"") -> GTX | I10: Zumgoity | J10: =_xlfn.XLOOKUP(I10,accounts!A:A,accounts!B:B,"") -> medical | K10: =_xlfn.XLOOKUP(I10,accounts!A:A,accounts!F:F,"") -> Mid-Market | L10: Won | M10: Advanced Technology | N10: Cobblepot Exports | O10: 42675 | P10: 42797 | Q10: =_xlfn.XLOOKUP(G10,products!A:A,products!C:C,"") -> 1096 | R10: 46 | S10: =Q10*R10 -> 50416
A11: HAXMC4IX | B11: Acquisition | C11: James Ascencio | D11: =_xlfn.XLOOKUP(C11,sales_teams!A:A,sales_teams!B:B,"") -> W249222 | E11: =_xlfn.XLOOKUP(C11,sales_teams!A:A,sales_teams!C:C,"") -> Summer Sewald | F11: =_xlfn.XLOOKUP(C11,sales_teams!A:A,sales_teams!D:D,"") -> West | G11: MG Advanced | H11: =_xlfn.XLOOKUP(G11,products!A:A,products!B:B,"") -> MG | J11: =_xlfn.XLOOKUP(I11,accounts!A:A,accounts!B:B,"") -> 0 | K11: =_xlfn.XLOOKUP(I11,accounts!A:A,accounts!F:F,"") -> 0 | L11: Engaging | N11: TBD | O11: 42677 | Q11: =_xlfn.XLOOKUP(G11,products!A:A,products!C:C,"") -> 3393 | R11: 33 | S11: =Q11*R11 -> 111969
A12: NL3JZH1Z | B12: Retention | C12: Anna Snelling | D12: =_xlfn.XLOOKUP(C12,sales_teams!A:A,sales_teams!B:B,"") -> C265891 | E12: =_xlfn.XLOOKUP(C12,sales_teams!A:A,sales_teams!C:C,"") -> Dustin Brinkmann | F12: =_xlfn.XLOOKUP(C12,sales_teams!A:A,sales_teams!D:D,"") -> Central | G12: MG Special | H12: =_xlfn.XLOOKUP(G12,products!A:A,products!B:B,"") -> MG | I12: Bioholding | J12: =_xlfn.XLOOKUP(I12,accounts!A:A,accounts!B:B,"") -> medical | K12: =_xlfn.XLOOKUP(I12,accounts!A:A,accounts!F:F,"") -> Mid-Market | L12: Won | M12: Brand Uniqueness | N12: Cobblepot Exports | O12: 42678 | P12: 42804 | Q12: =_xlfn.XLOOKUP(G12,products!A:A,products!C:C,"") -> 55 | R12: 40 | S12: =Q12*R12 -> 2200
A13: KWVA7VR1 | B13: Expansion | C13: Gladys Colclough | D13: =_xlfn.XLOOKUP(C13,sales_teams!A:A,sales_teams!B:B,"") -> C130664 | E13: =_xlfn.XLOOKUP(C13,sales_teams!A:A,sales_teams!C:C,"") -> Melvin Marxen | F13: =_xlfn.XLOOKUP(C13,sales_teams!A:A,sales_teams!D:D,"") -> Central | G13: GTX Pro | H13: =_xlfn.XLOOKUP(G13,products!A:A,products!B:B,"") -> GTX | I13: Genco Pura Olive Oil Company | J13: =_xlfn.XLOOKUP(I13,accounts!A:A,accounts!B:B,"") -> retail | K13: =_xlfn.XLOOKUP(I13,accounts!A:A,accounts!F:F,"") -> Mid-Market | L13: Lost | M13: Budget Misalignment | N13: Cobblepot Exports | O13: 42678 | P13: 42812 | Q13: =_xlfn.XLOOKUP(G13,products!A:A,products!C:C,"") -> 4821 | R13: 25 | S13: =Q13*R13 -> 120525
A14: S8DX3XOU | B14: Retention | C14: James Ascencio | D14: =_xlfn.XLOOKUP(C14,sales_teams!A:A,sales_teams!B:B,"") -> W249222 | E14: =_xlfn.XLOOKUP(C14,sales_teams!A:A,sales_teams!C:C,"") -> Summer Sewald | F14: =_xlfn.XLOOKUP(C14,sales_teams!A:A,sales_teams!D:D,"") -> West | G14: GTX Plus Pro | H14: =_xlfn.XLOOKUP(G14,products!A:A,products!B:B,"") -> GTX | I14: Sunnamplex | J14: =_xlfn.XLOOKUP(I14,accounts!A:A,accounts!B:B,"") -> marketing | K14: =_xlfn.XLOOKUP(I14,accounts!A:A,accounts!F:F,"") -> Mid-Market | L14: Won | M14: Executive Relationship | N14: Cobblepot Exports | O14: 42678 | P14: 42804 | Q14: =_xlfn.XLOOKUP(G14,products!A:A,products!C:C,"") -> 5482 | R14: 12 | S14: =Q14*R14 -> 65784
A15: ENB2XD8G | B15: Acquisition | C15: Maureen Marcano | D15: =_xlfn.XLOOKUP(C15,sales_teams!A:A,sales_teams!B:B,"") -> W960943 | E15: =_xlfn.XLOOKUP(C15,sales_teams!A:A,sales_teams!C:C,"") -> Summer Sewald | F15: =_xlfn.XLOOKUP(C15,sales_teams!A:A,sales_teams!D:D,"") -> West | G15: GTX Plus Pro | H15: =_xlfn.XLOOKUP(G15,products!A:A,products!B:B,"") -> GTX | I15: Sonron | J15: =_xlfn.XLOOKUP(I15,accounts!A:A,accounts!B:B,"") -> telecommunications | K15: =_xlfn.XLOOKUP(I15,accounts!A:A,accounts!F:F,"") -> Enterprise | L15: Won | M15: Strategic Timing | N15: Cobblepot Exports | O15: 42678 | P15: 42800 | Q15: =_xlfn.XLOOKUP(G15,products!A:A,products!C:C,"") -> 5482 | R15: 47 | S15: =Q15*R15 -> 257654
A16: 09YE9QOV | B16: Acquisition | C16: Hayden Neloms | D16: =_xlfn.XLOOKUP(C16,sales_teams!A:A,sales_teams!B:B,"") -> W815792 | E16: =_xlfn.XLOOKUP(C16,sales_teams!A:A,sales_teams!C:C,"") -> Celia Rouche | F16: =_xlfn.XLOOKUP(C16,sales_teams!A:A,sales_teams!D:D,"") -> West | G16: MG Advanced | H16: =_xlfn.XLOOKUP(G16,products!A:A,products!B:B,"") -> MG | I16: Finjob | J16: =_xlfn.XLOOKUP(I16,accounts!A:A,accounts!B:B,"") -> employment | K16: =_xlfn.XLOOKUP(I16,accounts!A:A,accounts!F:F,"") -> Mid-Market | L16: Won | M16: Product Superiority | N16: Enigma Analytics | O16: 42679 | P16: 42805 | Q16: =_xlfn.XLOOKUP(G16,products!A:A,products!C:C,"") -> 3393 | R16: 32 | S16: =Q16*R16 -> 108576
A17: 3F5MZNEH | B17: Diversification | C17: Rosalina Dieter | D17: =_xlfn.XLOOKUP(C17,sales_teams!A:A,sales_teams!B:B,"") -> W100826 | E17: =_xlfn.XLOOKUP(C17,sales_teams!A:A,sales_teams!C:C,"") -> Celia Rouche | F17: =_xlfn.XLOOKUP(C17,sales_teams!A:A,sales_teams!D:D,"") -> West | G17: MG Special | H17: =_xlfn.XLOOKUP(G17,products!A:A,products!B:B,"") -> MG | I17: Sonron | J17: =_xlfn.XLOOKUP(I17,accounts!A:A,accounts!B:B,"") -> telecommunications | K17: =_xlfn.XLOOKUP(I17,accounts!A:A,accounts!F:F,"") -> Enterprise | L17: Lost | M17: Strategic Pivot | N17: Enigma Analytics | O17: 42679 | P17: 42797 | Q17: =_xlfn.XLOOKUP(G17,products!A:A,products!C:C,"") -> 55 | R17: 11 | S17: =Q17*R17 -> 605
A18: M6WEJXC0 | B18: Retention | C18: Rosalina Dieter | D18: =_xlfn.XLOOKUP(C18,sales_teams!A:A,sales_teams!B:B,"") -> W100826 | E18: =_xlfn.XLOOKUP(C18,sales_teams!A:A,sales_teams!C:C,"") -> Celia Rouche | F18: =_xlfn.XLOOKUP(C18,sales_teams!A:A,sales_teams!D:D,"") -> West | G18: MG Advanced | H18: =_xlfn.XLOOKUP(G18,products!A:A,products!B:B,"") -> MG | I18: Scotfind | J18: =_xlfn.XLOOKUP(I18,accounts!A:A,accounts!B:B,"") -> software | K18: =_xlfn.XLOOKUP(I18,accounts!A:A,accounts!F:F,"") -> Enterprise | L18: Won | M18: Strategic Timing | N18: Cobblepot Exports | O18: 42679 | P18: 42800 | Q18: =_xlfn.XLOOKUP(G18,products!A:A,products!C:C,"") -> 3393 | R18: 37 | S18: =Q18*R18 -> 125541
A19: 6PTR7VBR | B19: Diversification | C19: Versie Hillebrand | D19: =_xlfn.XLOOKUP(C19,sales_teams!A:A,sales_teams!B:B,"") -> C234829 | E19: =_xlfn.XLOOKUP(C19,sales_teams!A:A,sales_teams!C:C,"") -> Dustin Brinkmann | F19: =_xlfn.XLOOKUP(C19,sales_teams!A:A,sales_teams!D:D,"") -> Central | G19: MG Special | H19: =_xlfn.XLOOKUP(G19,products!A:A,products!B:B,"") -> MG | I19: Treequote | J19: =_xlfn.XLOOKUP(I19,accounts!A:A,accounts!B:B,"") -> telecommunications | K19: =_xlfn.XLOOKUP(I19,accounts!A:A,accounts!F:F,"") -> Enterprise | L19: Won | M19: Brand Uniqueness | N19: Cobblepot Exports | O19: 42680 | P19: 42799 | Q19: =_xlfn.XLOOKUP(G19,products!A:A,products!C:C,"") -> 55 | R19: 35 | S19: =Q19*R19 -> 1925
A20: 902REDPA | B20: Retention | C20: Daniell Hammack | D20: =_xlfn.XLOOKUP(C20,sales_teams!A:A,sales_teams!B:B,"") -> E372575 | E20: =_xlfn.XLOOKUP(C20,sales_teams!A:A,sales_teams!C:C,"") -> Rocco Neubert | F20: =_xlfn.XLOOKUP(C20,sales_teams!A:A,sales_teams!D:D,"") -> East | G20: GTX Pro | H20: =_xlfn.XLOOKUP(G20,products!A:A,products!B:B,"") -> GTX | I20: Xx-zobam | J20: =_xlfn.XLOOKUP(I20,accounts!A:A,accounts!B:B,"") -> entertainment | K20: =_xlfn.XLOOKUP(I20,accounts!A:A,accounts!F:F,"") -> Enterprise | L20: Lost | M20: Strategic Pivot | N20: Enigma Analytics | O20: 42681 | P20: 42803 | Q20: =_xlfn.XLOOKUP(G20,products!A:A,products!C:C,"") -> 4821 | R20: 19 | S20: =Q20*R20 -> 91599
A21: 5J9CMGDV | B21: Acquisition | C21: Elease Gluck | D21: =_xlfn.XLOOKUP(C21,sales_teams!A:A,sales_teams!B:B,"") -> W172727 | E21: =_xlfn.XLOOKUP(C21,sales_teams!A:A,sales_teams!C:C,"") -> Celia Rouche | F21: =_xlfn.XLOOKUP(C21,sales_teams!A:A,sales_teams!D:D,"") -> West | G21: MG Special | H21: =_xlfn.XLOOKUP(G21,products!A:A,products!B:B,"") -> MG | I21: Rantouch | J21: =_xlfn.XLOOKUP(I21,accounts!A:A,accounts!B:B,"") -> telecommunications | K21: =_xlfn.XLOOKUP(I21,accounts!A:A,accounts!F:F,"") -> Mid-Market | L21: Won | M21: Brand Uniqueness | N21: Ivy Green-Tech | O21: 42681 | P21: 42802 | Q21: =_xlfn.XLOOKUP(G21,products!A:A,products!C:C,"") -> 55 | R21: 34 | S21: =Q21*R21 -> 1870
A22: JJXRR8R6 | B22: Expansion | C22: James Ascencio | D22: =_xlfn.XLOOKUP(C22,sales_teams!A:A,sales_teams!B:B,"") -> W249222 | E22: =_xlfn.XLOOKUP(C22,sales_teams!A:A,sales_teams!C:C,"") -> Summer Sewald | F22: =_xlfn.XLOOKUP(C22,sales_teams!A:A,sales_teams!D:D,"") -> West | G22: GTX Plus Pro | H22: =_xlfn.XLOOKUP(G22,products!A:A,products!B:B,"") -> GTX | I22: Fasehatice | J22: =_xlfn.XLOOKUP(I22,accounts!A:A,accounts!B:B,"") -> retail | K22: =_xlfn.XLOOKUP(I22,accounts!A:A,accounts!F:F,"") -> Enterprise | L22: Lost | M22: Budget Misalignment | N22: Enigma Analytics | O22: 42681 | P22: 42811 | Q22: =_xlfn.XLOOKUP(G22,products!A:A,products!C:C,"") -> 5482 | R22: 33 | S22: =Q22*R22 -> 180906
A23: WF4HA5NW | B23: Diversification | C23: Moses Frase | D23: =_xlfn.XLOOKUP(C23,sales_teams!A:A,sales_teams!B:B,"") -> C62195 | E23: =_xlfn.XLOOKUP(C23,sales_teams!A:A,sales_teams!C:C,"") -> Dustin Brinkmann | F23: =_xlfn.XLOOKUP(C23,sales_teams!A:A,sales_teams!D:D,"") -> Central | G23: MG Special | H23: =_xlfn.XLOOKUP(G23,products!A:A,products!B:B,"") -> MG | I23: Ron-tech | J23: =_xlfn.XLOOKUP(I23,accounts!A:A,accounts!B:B,"") -> medical | K23: =_xlfn.XLOOKUP(I23,accounts!A:A,accounts!F:F,"") -> Enterprise | L23: Won | M23: Strategic Timing | N23: Enigma Analytics | O23: 42681 | P23: 42812 | Q23: =_xlfn.XLOOKUP(G23,products!A:A,products!C:C,"") -> 55 | R23: 11 | S23: =Q23*R23 -> 605
... A26: SBCR987L | B26: Retention | C26: Kami Bicknell | D26: =_xlfn.XLOOKUP(C26,sales_teams!A:A,sales_teams!B:B,"") -> W596440 | E26: =_xlfn.XLOOKUP(C26,sales_teams!A:A,sales_teams!C:C,"") -> Summer Sewald | F26: =_xlfn.XLOOKUP(C26,sales_teams!A:A,sales_teams!D:D,"") -> West | G26: GTX Basic | H26: =_xlfn.XLOOKUP(G26,products!A:A,products!B:B,"") -> GTX | I26: Zoomit | J26: =_xlfn.XLOOKUP(I26,accounts!A:A,accounts!B:B,"") -> entertainment | K26: =_xlfn.XLOOKUP(I26,accounts!A:A,accounts!F:F,"") -> SMB | L26: Won | M26: Strategic Timing | N26: Ivy Green-Tech | O26: 42684 | P26: 42817 | Q26: =_xlfn.XLOOKUP(G26,products!A:A,products!C:C,"") -> 550 | R26: 20 | S26: =Q26*R26 -> 11000
A27: UP409DSB | B27: Diversification | C27: Maureen Marcano | D27: =_xlfn.XLOOKUP(C27,sales_teams!A:A,sales_teams!B:B,"") -> W960943 | E27: =_xlfn.XLOOKUP(C27,sales_teams!A:A,sales_teams!C:C,"") -> Summer Sewald | F27: =_xlfn.XLOOKUP(C27,sales_teams!A:A,sales_teams!D:D,"") -> West | G27: MG Advanced | H27: =_xlfn.XLOOKUP(G27,products!A:A,products!B:B,"") -> MG | I27: Ganjaflex | J27: =_xlfn.XLOOKUP(I27,accounts!A:A,accounts!B:B,"") -> retail | K27: =_xlfn.XLOOKUP(I27,accounts!A:A,accounts!F:F,"") -> Enterprise | L27: Engaging | N27: TBD | O27: 42684 | Q27: =_xlfn.XLOOKUP(G27,products!A:A,products!C:C,"") -> 3393 | R27: 48 | S27: =Q27*R27 -> 162864
A28: JSD4APT2 | B28: Expansion | C28: Versie Hillebrand | D28: =_xlfn.XLOOKUP(C28,sales_teams!A:A,sales_teams!B:B,"") -> C234829 | E28: =_xlfn.XLOOKUP(C28,sales_teams!A:A,sales_teams!C:C,"") -> Dustin Brinkmann | F28: =_xlfn.XLOOKUP(C28,sales_teams!A:A,sales_teams!D:D,"") -> Central | G28: MG Special | H28: =_xlfn.XLOOKUP(G28,products!A:A,products!B:B,"") -> MG | I28: Bioholding | J28: =_xlfn.XLOOKUP(I28,accounts!A:A,accounts!B:B,"") -> medical | K28: =_xlfn.XLOOKUP(I28,accounts!A:A,accounts!F:F,"") -> Mid-Market | L28: Won | M28: Executive Relationship | N28: Ivy Green-Tech | O28: 42684 | P28: 42806 | Q28: =_xlfn.XLOOKUP(G28,products!A:A,products!C:C,"") -> 55 | R28: 15 | S28: =Q28*R28 -> 825
A29: AO9Z2D17 | B29: Retention | C29: Violet Mclelland | D29: =_xlfn.XLOOKUP(C29,sales_teams!A:A,sales_teams!B:B,"") -> E152967 | E29: =_xlfn.XLOOKUP(C29,sales_teams!A:A,sales_teams!C:C,"") -> Cara Losch | F29: =_xlfn.XLOOKUP(C29,sales_teams!A:A,sales_teams!D:D,"") -> East | G29: GTX Plus Pro | H29: =_xlfn.XLOOKUP(G29,products!A:A,products!B:B,"") -> GTX | I29: Xx-zobam | J29: =_xlfn.XLOOKUP(I29,accounts!A:A,accounts!B:B,"") -> entertainment | K29: =_xlfn.XLOOKUP(I29,accounts!A:A,accounts!F:F,"") -> Enterprise | L29: Lost | M29: Budget Misalignment | N29: Ivy Green-Tech | O29: 42684 | P29: 42805 | Q29: =_xlfn.XLOOKUP(G29,products!A:A,products!C:C,"") -> 5482 | R29: 46 | S29: =Q29*R29 -> 252172
A30: 5M58DTJK | B30: Retention | C30: Elease Gluck | D30: =_xlfn.XLOOKUP(C30,sales_teams!A:A,sales_teams!B:B,"") -> W172727 | E30: =_xlfn.XLOOKUP(C30,sales_teams!A:A,sales_teams!C:C,"") -> Celia Rouche | F30: =_xlfn.XLOOKUP(C30,sales_teams!A:A,sales_teams!D:D,"") -> West | G30: MG Special | H30: =_xlfn.XLOOKUP(G30,products!A:A,products!B:B,"") -> MG | I30: Cheers | J30: =_xlfn.XLOOKUP(I30,accounts!A:A,accounts!B:B,"") -> entertainment | K30: =_xlfn.XLOOKUP(I30,accounts!A:A,accounts!F:F,"") -> Enterprise | L30: Won | M30: Advanced Technology | N30: Ivy Green-Tech | O30: 42685 | P30: 42799 | Q30: =_xlfn.XLOOKUP(G30,products!A:A,products!C:C,"") -> 55 | R30: 19 | S30: =Q30*R30 -> 1045
A31: KNY1OSAB | B31: Retention | C31: Maureen Marcano | D31: =_xlfn.XLOOKUP(C31,sales_teams!A:A,sales_teams!B:B,"") -> W960943 | E31: =_xlfn.XLOOKUP(C31,sales_teams!A:A,sales_teams!C:C,"") -> Summer Sewald | F31: =_xlfn.XLOOKUP(C31,sales_teams!A:A,sales_teams!D:D,"") -> West | G31: GTX Pro | H31: =_xlfn.XLOOKUP(G31,products!A:A,products!B:B,"") -> GTX | I31: Labdrill | J31: =_xlfn.XLOOKUP(I31,accounts!A:A,accounts!B:B,"") -> medical | K31: =_xlfn.XLOOKUP(I31,accounts!A:A,accounts!F:F,"") -> Enterprise | L31: Won | M31: Strategic Timing | N31: Ivy Green-Tech | O31: 42685 | P31: 42808 | Q31: =_xlfn.XLOOKUP(G31,products!A:A,products!C:C,"") -> 4821 | R31: 12 | S31: =Q31*R31 -> 57852
A32: EAZDUUM9 | B32: Acquisition | C32: Rosie Papadopoulos | D32: =_xlfn.XLOOKUP(C32,sales_teams!A:A,sales_teams!B:B,"") -> E777204 | E32: =_xlfn.XLOOKUP(C32,sales_teams!A:A,sales_teams!C:C,"") -> Cara Losch | F32: =_xlfn.XLOOKUP(C32,sales_teams!A:A,sales_teams!D:D,"") -> East | G32: MG Advanced | H32: =_xlfn.XLOOKUP(G32,products!A:A,products!B:B,"") -> MG | I32: Zotware | J32: =_xlfn.XLOOKUP(I32,accounts!A:A,accounts!B:B,"") -> software | K32: =_xlfn.XLOOKUP(I32,accounts!A:A,accounts!F:F,"") -> Enterprise | L32: Lost | M32: Competitor Selection | N32: Falconia Enterprises | O32: 42685 | P32: 42795 | Q32: =_xlfn.XLOOKUP(G32,products!A:A,products!C:C,"") -> 3393 | R32: 2 | S32: =Q32*R32 -> 6786
A33: 2STUSOFE | B33: Retention | C33: Versie Hillebrand | D33: =_xlfn.XLOOKUP(C33,sales_teams!A:A,sales_teams!B:B,"") -> C234829 | E33: =_xlfn.XLOOKUP(C33,sales_teams!A:A,sales_teams!C:C,"") -> Dustin Brinkmann | F33: =_xlfn.XLOOKUP(C33,sales_teams!A:A,sales_teams!D:D,"") -> Central | G33: MG Special | H33: =_xlfn.XLOOKUP(G33,products!A:A,products!B:B,"") -> MG | I33: dambase | J33: =_xlfn.XLOOKUP(I33,accounts!A:A,accounts!B:B,"") -> marketing | K33: =_xlfn.XLOOKUP(I33,accounts!A:A,accounts!F:F,"") -> Mid-Market | L33: Won | M33: Brand Uniqueness | N33: Falconia Enterprises | O33: 42685 | P33: 42797 | Q33: =_xlfn.XLOOKUP(G33,products!A:A,products!C:C,"") -> 55 | R33: 3 | S33: =Q33*R33 -> 165
A34: JYKM0B00 | B34: Expansion | C34: James Ascencio | D34: =_xlfn.XLOOKUP(C34,sales_teams!A:A,sales_teams!B:B,"") -> W249222 | E34: =_xlfn.XLOOKUP(C34,sales_teams!A:A,sales_teams!C:C,"") -> Summer Sewald | F34: =_xlfn.XLOOKUP(C34,sales_teams!A:A,sales_teams!D:D,"") -> West | G34: GTX Pro | H34: =_xlfn.XLOOKUP(G34,products!A:A,products!B:B,"") -> GTX | I34: Xx-holding | J34: =_xlfn.XLOOKUP(I34,accounts!A:A,accounts!B:B,"") -> finance | K34: =_xlfn.XLOOKUP(I34,accounts!A:A,accounts!F:F,"") -> Enterprise | L34: Won | M34: Executive Relationship | N34: Enigma Analytics | O34: 42686 | P34: 42800 | Q34: =_xlfn.XLOOKUP(G34,products!A:A,products!C:C,"") -> 4821 | R34: 2 | S34: =Q34*R34 -> 9642
A35: KU28360J | B35: Acquisition | C35: Kary Hendrixson | D35: =_xlfn.XLOOKUP(C35,sales_teams!A:A,sales_teams!B:B,"") -> W674591 | E35: =_xlfn.XLOOKUP(C35,sales_teams!A:A,sales_teams!C:C,"") -> Summer Sewald | F35: =_xlfn.XLOOKUP(C35,sales_teams!A:A,sales_teams!D:D,"") -> West | G35: GTX Basic | H35: =_xlfn.XLOOKUP(G35,products!A:A,products!B:B,"") -> GTX | I35: Fasehatice | J35: =_xlfn.XLOOKUP(I35,accounts!A:A,accounts!B:B,"") -> retail | K35: =_xlfn.XLOOKUP(I35,accounts!A:A,accounts!F:F,"") -> Enterprise | L35: Won | M35: Product Superiority | N35: Ivy Green-Tech | O35: 42686 | P35: 42813 | Q35: =_xlfn.XLOOKUP(G35,products!A:A,products!C:C,"") -> 550 | R35: 4 | S35: =Q35*R35 -> 2200
A36: N4SD17JR | B36: Retention | C36: Reed Clapper | D36: =_xlfn.XLOOKUP(C36,sales_teams!A:A,sales_teams!B:B,"") -> E571180 | E36: =_xlfn.XLOOKUP(C36,sales_teams!A:A,sales_teams!C:C,"") -> Rocco Neubert | F36: =_xlfn.XLOOKUP(C36,sales_teams!A:A,sales_teams!D:D,"") -> East | G36: GTX Basic | H36: =_xlfn.XLOOKUP(G36,products!A:A,products!B:B,"") -> GTX | I36: Acme Corporation | J36: =_xlfn.XLOOKUP(I36,accounts!A:A,accounts!B:B,"") -> technolgy | K36: =_xlfn.XLOOKUP(I36,accounts!A:A,accounts!F:F,"") -> Mid-Market | L36: Won | M36: Executive Relationship | N36: Enigma Analytics | O36: 42686 | P36: 42795 | Q36: =_xlfn.XLOOKUP(G36,products!A:A,products!C:C,"") -> 550 | R36: 5 | S36: =Q36*R36 -> 2750
A37: E67P9Y3Q | B37: Acquisition | C37: Rosalina Dieter | D37: =_xlfn.XLOOKUP(C37,sales_teams!A:A,sales_teams!B:B,"") -> W100826 | E37: =_xlfn.XLOOKUP(C37,sales_teams!A:A,sales_teams!C:C,"") -> Celia Rouche | F37: =_xlfn.XLOOKUP(C37,sales_teams!A:A,sales_teams!D:D,"") -> West | G37: GTX Basic | H37: =_xlfn.XLOOKUP(G37,products!A:A,products!B:B,"") -> GTX | I37: Green-Plus | J37: =_xlfn.XLOOKUP(I37,accounts!A:A,accounts!B:B,"") -> services | K37: =_xlfn.XLOOKUP(I37,accounts!A:A,accounts!F:F,"") -> Mid-Market | L37: Won | M37: Product Superiority | N37: Enigma Analytics | O37: 42686 | P37: 42797 | Q37: =_xlfn.XLOOKUP(G37,products!A:A,products!C:C,"") -> 550 | R37: 13 | S37: =Q37*R37 -> 7150
A38: AT3MMVIS | B38: Diversification | C38: Wilburn Farren | D38: =_xlfn.XLOOKUP(C38,sales_teams!A:A,sales_teams!B:B,"") -> E680402 | E38: =_xlfn.XLOOKUP(C38,sales_teams!A:A,sales_teams!C:C,"") -> Cara Losch | F38: =_xlfn.XLOOKUP(C38,sales_teams!A:A,sales_teams!D:D,"") -> East | G38: MG Advanced | H38: =_xlfn.XLOOKUP(G38,products!A:A,products!B:B,"") -> MG | I38: The New York Inquirer | J38: =_xlfn.XLOOKUP(I38,accounts!A:A,accounts!B:B,"") -> medical | K38: =_xlfn.XLOOKUP(I38,accounts!A:A,accounts!F:F,"") -> SMB | L38: Won | M38: Product Superiority | N38: Enigma Analytics | O38: 42686 | P38: 42801 | Q38: =_xlfn.XLOOKUP(G38,products!A:A,products!C:C,"") -> 3393 | R38: 20 | S38: =Q38*R38 -> 67860
A39: REJ11LRY | B39: Expansion | C39: Garret Kinder | D39: =_xlfn.XLOOKUP(C39,sales_teams!A:A,sales_teams!B:B,"") -> E86134 | E39: =_xlfn.XLOOKUP(C39,sales_teams!A:A,sales_teams!C:C,"") -> Cara Losch | F39: =_xlfn.XLOOKUP(C39,sales_teams!A:A,sales_teams!D:D,"") -> East | G39: GTX Plus Basic | H39: =_xlfn.XLOOKUP(G39,products!A:A,products!B:B,"") -> GTX | I39: Mathtouch | J39: =_xlfn.XLOOKUP(I39,accounts!A:A,accounts!B:B,"") -> marketing | K39: =_xlfn.XLOOKUP(I39,accounts!A:A,accounts!F:F,"") -> Enterprise | L39: Won | M39: Product Superiority | N39: Ivy Green-Tech | O39: 42687 | P39: 42808 | Q39: =_xlfn.XLOOKUP(G39,products!A:A,products!C:C,"") -> 1096 | R39: 23 | S39: =Q39*R39 -> 25208
... A43: CZVN09WN | B43: Retention | C43: Darcel Schlecht | D43: =_xlfn.XLOOKUP(C43,sales_teams!A:A,sales_teams!B:B,"") -> C486814 | E43: =_xlfn.XLOOKUP(C43,sales_teams!A:A,sales_teams!C:C,"") -> Melvin Marxen | F43: =_xlfn.XLOOKUP(C43,sales_teams!A:A,sales_teams!D:D,"") -> Central | G43: GTX Plus Basic | H43: =_xlfn.XLOOKUP(G43,products!A:A,products!B:B,"") -> GTX | I43: Konmatfix | J43: =_xlfn.XLOOKUP(I43,accounts!A:A,accounts!B:B,"") -> marketing | K43: =_xlfn.XLOOKUP(I43,accounts!A:A,accounts!F:F,"") -> Mid-Market | L43: Won | M43: Executive Relationship | N43: Cobblepot Exports | O43: 42688 | P43: 42814 | Q43: =_xlfn.XLOOKUP(G43,products!A:A,products!C:C,"") -> 1096 | R43: 40 | S43: =Q43*R43 -> 43840
A44: EG7OFLFR | B44: Expansion | C44: Kami Bicknell | D44: =_xlfn.XLOOKUP(C44,sales_teams!A:A,sales_teams!B:B,"") -> W596440 | E44: =_xlfn.XLOOKUP(C44,sales_teams!A:A,sales_teams!C:C,"") -> Summer Sewald | F44: =_xlfn.XLOOKUP(C44,sales_teams!A:A,sales_teams!D:D,"") -> West | G44: GTX Basic | H44: =_xlfn.XLOOKUP(G44,products!A:A,products!B:B,"") -> GTX | J44: =_xlfn.XLOOKUP(I44,accounts!A:A,accounts!B:B,"") -> 0 | K44: =_xlfn.XLOOKUP(I44,accounts!A:A,accounts!F:F,"") -> 0 | L44: Engaging | N44: TBD | O44: 42688 | Q44: =_xlfn.XLOOKUP(G44,products!A:A,products!C:C,"") -> 550 | R44: 12 | S44: =Q44*R44 -> 6600
A45: 30UQWUKB | B45: Expansion | C45: Marty Freudenburg | D45: =_xlfn.XLOOKUP(C45,sales_teams!A:A,sales_teams!B:B,"") -> C234392 | E45: =_xlfn.XLOOKUP(C45,sales_teams!A:A,sales_teams!C:C,"") -> Melvin Marxen | F45: =_xlfn.XLOOKUP(C45,sales_teams!A:A,sales_teams!D:D,"") -> Central | G45: GTX Plus Basic | H45: =_xlfn.XLOOKUP(G45,products!A:A,products!B:B,"") -> GTX | I45: Genco Pura Olive Oil Company | J45: =_xlfn.XLOOKUP(I45,accounts!A:A,accounts!B:B,"") -> retail | K45: =_xlfn.XLOOKUP(I45,accounts!A:A,accounts!F:F,"") -> Mid-Market | L45: Won | M45: Advanced Technology | N45: Ivy Green-Tech | O45: 42689 | P45: 42814 | Q45: =_xlfn.XLOOKUP(G45,products!A:A,products!C:C,"") -> 1096 | R45: 26 | S45: =Q45*R45 -> 28496
...

Sheet sales_teams
A1: sales_agent | B1: sales_agent_id | C1: manager | D1: regional_office
A2: Anna Snelling | B2: C265891 | C2: Dustin Brinkmann | D2: Central
A3: Cecily Lampkin | B3: C163925 | C3: Dustin Brinkmann | D3: Central
A4: Versie Hillebrand | B4: C234829 | C4: Dustin Brinkmann | D4: Central
A5: Lajuana Vencill | B5: C100201 | C5: Dustin Brinkmann | D5: Central
A6: Moses Frase | B6: C62195 | C6: Dustin Brinkmann | D6: Central
A7: Jonathan Berthelot | B7: C309699 | C7: Melvin Marxen | D7: Central
A8: Marty Freudenburg | B8: C234392 | C8: Melvin Marxen | D8: Central
A9: Gladys Colclough | B9: C130664 | C9: Melvin Marxen | D9: Central
A10: Niesha Huffines | B10: C961860 | C10: Melvin Marxen | D10: Central
A11: Darcel Schlecht | B11: C486814 | C11: Melvin Marxen | D11: Central
A12: Mei-Mei Johns | B12: C42503 | C12: Melvin Marxen | D12: Central
... A36: Carl Lin | B36: W324849 | C36: Summer Sewald | D36: West

Sheet products
A1: product | B1: series | C1: sales_price
A2: GTX Basic | B2: GTX | C2: 550
A3: GTX Pro | B3: GTX | C3: 4821
A4: MG Special | B4: MG | C4: 55
A5: MG Advanced | B5: MG | C5: 3393
A6: GTX Plus Pro | B6: GTX | C6: 5482
A7: GTX Plus Basic | B7: GTX | C7: 1096
A8: GTK 500 | B8: GTK | C8: 26768

Sheet accounts
A1: account | B1: sector | C1: year_established | D1: revenue | E1: employees | F1: account_tier | G1: office_location
A2: Acme Corporation | B2: technolgy | C2: 1996 | D2: =SUMIFS(sales_pipeline!S:S, sales_pipeline!I:I, A2, sales_pipeline!L:L, "Won") -> 2530983 | E2: 2822 | F2: {=_xlfn.IFS(E2<1000, "SMB", E2<=5000, "Mid-Market", E2>5000, "Enterprise")} -> Mid-Market | G2: United States
A3: Betasoloin | B3: medical | C3: 1999 | D3: =SUMIFS(sales_pipeline!S:S, sales_pipeline!I:I, A3, sales_pipeline!L:L, "Won") -> 2399963 | E3: 495 | F3: {=_xlfn.IFS(E3<1000, "SMB", E3<=5000, "Mid-Market", E3>5000, "Enterprise")} -> SMB | G3: United States
A4: Betatech | B4: medical | C4: 1986 | D4: =SUMIFS(sales_pipeline!S:S, sales_pipeline!I:I, A4, sales_pipeline!L:L, "Won") -> 2459593 | E4: 1185 | F4: {=_xlfn.IFS(E4<1000, "SMB", E4<=5000, "Mid-Market", E4>5000, "Enterprise")} -> Mid-Market | G4: Kenya
A5: Bioholding | B5: medical | C5: 2012 | D5: =SUMIFS(sales_pipeline!S:S, sales_pipeline!I:I, A5, sales_pipeline!L:L, "Won") -> 2419653 | E5: 1356 | F5: {=_xlfn.IFS(E5<1000, "SMB", E5<=5000, "Mid-Market", E5>5000, "Enterprise")} -> Mid-Market | G5: Philipines
A6: Bioplex | B6: medical | C6: 1991 | D6: =SUMIFS(sales_pipeline!S:S, sales_pipeline!I:I, A6, sales_pipeline!L:L, "Won") -> 1759072 | E6: 1016 | F6: {=_xlfn.IFS(E6<1000, "SMB", E6<=5000, "Mid-Market", E6>5000, "Enterprise")} -> Mid-Market | G6: United States
A7: Blackzim | B7: retail | C7: 2009 | D7: =SUMIFS(sales_pipeline!S:S, sales_pipeline!I:I, A7, sales_pipeline!L:L, "Won") -> 1938216 | E7: 1588 | F7: {=_xlfn.IFS(E7<1000, "SMB", E7<=5000, "Mid-Market", E7>5000, "Enterprise")} -> Mid-Market | G7: United States
A8: Bluth Company | B8: technolgy | C8: 1993 | D8: =SUMIFS(sales_pipeline!S:S, sales_pipeline!I:I, A8, sales_pipeline!L:L, "Won") -> 1474886 | E8: 3027 | F8: {=_xlfn.IFS(E8<1000, "SMB", E8<=5000, "Mid-Market", E8>5000, "Enterprise")} -> Mid-Market | G8: United States
A9: Bubba Gump | B9: software | C9: 2002 | D9: =SUMIFS(sales_pipeline!S:S, sales_pipeline!I:I, A9, sales_pipeline!L:L, "Won") -> 2405614 | E9: 2253 | F9: {=_xlfn.IFS(E9<1000, "SMB", E9<=5000, "Mid-Market", E9>5000, "Enterprise")} -> Mid-Market | G9: United States
A10: Cancity | B10: retail | C10: 2001 | D10: =SUMIFS(sales_pipeline!S:S, sales_pipeline!I:I, A10, sales_pipeline!L:L, "Won") -> 2918715 | E10: 2448 | F10: {=_xlfn.IFS(E10<1000, "SMB", E10<=5000, "Mid-Market", E10>5000, "Enterprise")} -> Mid-Market | G10: United States
A11: Cheers | B11: entertainment | C11: 1993 | D11: =SUMIFS(sales_pipeline!S:S, sales_pipeline!I:I, A11, sales_pipeline!L:L, "Won") -> 5492763 | E11: 6472 | F11: {=_xlfn.IFS(E11<1000, "SMB", E11<=5000, "Mid-Market", E11>5000, "Enterprise")} -> Enterprise | G11: United States
A12: Codehow | B12: software | C12: 1998 | D12: =SUMIFS(sales_pipeline!S:S, sales_pipeline!I:I, A12, sales_pipeline!L:L, "Won") -> 3562106 | E12: 2641 | F12: {=_xlfn.IFS(E12<1000, "SMB", E12<=5000, "Mid-Market", E12>5000, "Enterprise")} -> Mid-Market | G12: United States
A13: Condax | B13: medical | C13: 2017 | D13: =SUMIFS(sales_pipeline!S:S, sales_pipeline!I:I, A13, sales_pipeline!L:L, "Won") -> 5099812 | E13: 9 | F13: {=_xlfn.IFS(E13<1000, "SMB", E13<=5000, "Mid-Market", E13>5000, "Enterprise")} -> SMB | G13: United States
... A86: Zumgoity | B86: medical | C86: 1984 | D86: =SUMIFS(sales_pipeline!S:S, sales_pipeline!I:I, A86, sales_pipeline!L:L, "Won") -> 2075752 | E86: 1210 | F86: {=_xlfn.IFS(E86<1000, "SMB", E86<=5000, "Mid-Market", E86>5000, "Enterprise")} -> Mid-Market | G86: United States
